<?xml version="1.0" encoding="utf-8" ?>
<!-- =================================================================================== -->
<!-- |    This document was autogenerated by xacro from /home/andrea/avatar_ws/src/avatar_description/robot/main/main2.urdf.xacro | -->
<!-- |    EDITING THIS FILE BY HAND IS NOT RECOMMENDED                                 | -->
<!-- =================================================================================== -->
<robot name="avatar">
    <link name="platform">
        
<inertial>
            <origin rpy="0 0 0" xyz="0.508 -0.754 0.184" />
            <mass value="24.338" />
            <inertia ixx="7.7969" ixy="0" ixz="0" iyy="6.1243" iyz="0" izz="12.4142" />
        </inertial>

        <visual>
            <origin rpy="1.5707963267949 0 0" xyz="0 0 0" />
            <geometry>
                <mesh filename="package://avatar_description/robot/platform/meshes/platform_visual.STL" />
            </geometry>
            <material name="">
                <color rgba="0.79216 0.81961 0.93333 1" />
            </material>
        </visual>
        <collision>
            <origin rpy="1.5707963267949 0 0" xyz="0 0 0" />
            <geometry>
                <mesh filename="package://avatar_description/robot/platform/meshes/platform_collision.STL" />
            </geometry>
        </collision>
    </link>
    <joint name="panda_joint_platform" type="fixed">
        <parent link="platform" />
        <child link="panda_link0" />
        <origin rpy="0 0 0" xyz="0.508 -0.753 0.23" />
    </joint>
    <link name="panda_link0">
        <visual>
            <geometry>
                <mesh filename="package://franka_description/meshes/visual/link0.dae" />
            </geometry>
        </visual>
        <collision>
            <origin rpy="0 1.57079632679 0" xyz="-0.075 0 0.06" />
            <geometry>
                <cylinder length="0.03" radius="0.06" />
            </geometry>
        </collision>
        <collision>
            <origin rpy="0 0 0" xyz="-0.06 0 0.06" />
            <geometry>
                <sphere radius="0.06" />
            </geometry>
        </collision>
        <collision>
            <origin rpy="0 0 0" xyz="-0.09 0 0.06" />
            <geometry>
                <sphere radius="0.06" />
            </geometry>
        </collision>
        
<inertial>
            <mass value="3.064" />
            <inertia ixx="0.03" iyy="0.03" izz="0.03" ixy="0.0" ixz="0.0" iyz="0.0" />
        </inertial>

    </link>
    <link name="panda_link1">
        <visual>
            <geometry>
                <mesh filename="package://franka_description/meshes/visual/link1.dae" />
            </geometry>
        </visual>
        <collision>
            <origin rpy="0 0 0" xyz="0 0 -0.1915" />
            <geometry>
                <cylinder length="0.2830" radius="0.06" />
            </geometry>
        </collision>
        <collision>
            <origin rpy="0 0 0" xyz="0 0 -0.333" />
            <geometry>
                <sphere radius="0.06" />
            </geometry>
        </collision>
        <collision>
            <origin rpy="0 0 0" xyz="0 0 -0.05" />
            <geometry>
                <sphere radius="0.06" />
            </geometry>
        </collision>
        
<inertial>
            <mass value="2.345" />
            <inertia ixx="0.03" iyy="0.03" izz="0.03" ixy="0.0" ixz="0.0" iyz="0.0" />
        </inertial>

    </link>
    <joint name="panda_joint1" type="revolute">
        <safety_controller k_position="100.0" k_velocity="40.0" soft_lower_limit="-2.8973" soft_upper_limit="2.8973" />
        <origin rpy="0 0 0" xyz="0 0 0.333" />
        <parent link="panda_link0" />
        <child link="panda_link1" />
        <axis xyz="0 0 1" />
        <limit effort="870" lower="-2.8973" upper="2.8973" velocity="2.1750" />
    </joint>
    <link name="panda_link2">
        <visual>
            <geometry>
                <mesh filename="package://franka_description/meshes/visual/link2.dae" />
            </geometry>
        </visual>
        <collision>
            <origin rpy="0 0 0" xyz="0 0 0" />
            <geometry>
                <cylinder length="0.12" radius="0.06" />
            </geometry>
        </collision>
        <collision>
            <origin rpy="0 0 0" xyz="0 0 -0.06" />
            <geometry>
                <sphere radius="0.06" />
            </geometry>
        </collision>
        <collision>
            <origin rpy="0 0 0" xyz="0 0 0.06" />
            <geometry>
                <sphere radius="0.06" />
            </geometry>
        </collision>
        
<inertial>
            <mass value="2.364" />
            <inertia ixx="0.03" iyy="0.03" izz="0.03" ixy="0.0" ixz="0.0" iyz="0.0" />
        </inertial>

    </link>
    <joint name="panda_joint2" type="revolute">
        <safety_controller k_position="100.0" k_velocity="40.0" soft_lower_limit="-1.7628" soft_upper_limit="1.7628" />
        <origin rpy="-1.57079632679 0 0" xyz="0 0 0" />
        <parent link="panda_link1" />
        <child link="panda_link2" />
        <axis xyz="0 0 1" />
        <limit effort="870" lower="-1.7628" upper="1.7628" velocity="2.1750" />
    </joint>
    <link name="panda_link3">
        <visual>
            <geometry>
                <mesh filename="package://franka_description/meshes/visual/link3.dae" />
            </geometry>
        </visual>
        <collision>
            <origin rpy="0 0 0" xyz="0 0 -0.145" />
            <geometry>
                <cylinder length="0.15" radius="0.06" />
            </geometry>
        </collision>
        <collision>
            <origin rpy="0 0 0" xyz="0 0 -0.22" />
            <geometry>
                <sphere radius="0.06" />
            </geometry>
        </collision>
        <collision>
            <origin rpy="0 0 0" xyz="0 0 -0.07" />
            <geometry>
                <sphere radius="0.06" />
            </geometry>
        </collision>
        
<inertial>
            <mass value="2.38" />
            <inertia ixx="0.03" iyy="0.03" izz="0.03" ixy="0.0" ixz="0.0" iyz="0.0" />
        </inertial>

    </link>
    <joint name="panda_joint3" type="revolute">
        <safety_controller k_position="100.0" k_velocity="40.0" soft_lower_limit="-2.8973" soft_upper_limit="2.8973" />
        <origin rpy="1.57079632679 0 0" xyz="0 -0.316 0" />
        <parent link="panda_link2" />
        <child link="panda_link3" />
        <axis xyz="0 0 1" />
        <limit effort="870" lower="-2.8973" upper="2.8973" velocity="2.1750" />
    </joint>
    <link name="panda_link4">
        <visual>
            <geometry>
                <mesh filename="package://franka_description/meshes/visual/link4.dae" />
            </geometry>
        </visual>
        <collision>
            <origin rpy="0 0 0" xyz="0 0 0" />
            <geometry>
                <cylinder length="0.12" radius="0.06" />
            </geometry>
        </collision>
        <collision>
            <origin rpy="0 0 0" xyz="0 0 0.06" />
            <geometry>
                <sphere radius="0.06" />
            </geometry>
        </collision>
        <collision>
            <origin rpy="0 0 0" xyz="0 0 -0.06" />
            <geometry>
                <sphere radius="0.06" />
            </geometry>
        </collision>
        
<inertial>
            <mass value="2.428" />
            <inertia ixx="0.03" iyy="0.03" izz="0.03" ixy="0.0" ixz="0.0" iyz="0.0" />
        </inertial>

    </link>
    <joint name="panda_joint4" type="revolute">
        <safety_controller k_position="100.0" k_velocity="40.0" soft_lower_limit="-3.0718" soft_upper_limit="-0.0698" />
        <origin rpy="1.57079632679 0 0" xyz="0.0825 0 0" />
        <parent link="panda_link3" />
        <child link="panda_link4" />
        <axis xyz="0 0 1" />
        <limit effort="870" lower="-3.0718" upper="-0.0698" velocity="2.1750" />
    </joint>
    <link name="panda_link5">
        <visual>
            <geometry>
                <mesh filename="package://franka_description/meshes/visual/link5.dae" />
            </geometry>
        </visual>
        <collision>
            <origin rpy="0 0 0" xyz="0 0 -0.26" />
            <geometry>
                <cylinder length="0.1" radius="0.06" />
            </geometry>
        </collision>
        <collision>
            <origin rpy="0 0 0" xyz="0 0 -0.31" />
            <geometry>
                <sphere radius="0.06" />
            </geometry>
        </collision>
        <collision>
            <origin rpy="0 0 0" xyz="0 0 -0.21" />
            <geometry>
                <sphere radius="0.06" />
            </geometry>
        </collision>
        <collision>
            <origin rpy="0 0 0" xyz="0 0.08 -0.13" />
            <geometry>
                <cylinder length="0.14" radius="0.025" />
            </geometry>
        </collision>
        <collision>
            <origin rpy="0 0 0" xyz="0 0.08 -0.06" />
            <geometry>
                <sphere radius="0.025" />
            </geometry>
        </collision>
        <collision>
            <origin rpy="0 0 0" xyz="0 0.08 -0.20" />
            <geometry>
                <sphere radius="0.025" />
            </geometry>
        </collision>
        
<inertial>
            <mass value="3.500" />
            <inertia ixx="0.03" iyy="0.03" izz="0.03" ixy="0.0" ixz="0.0" iyz="0.0" />
        </inertial>

    </link>
    <joint name="panda_joint5" type="revolute">
        <safety_controller k_position="100.0" k_velocity="40.0" soft_lower_limit="-2.8973" soft_upper_limit="2.8973" />
        <origin rpy="-1.57079632679 0 0" xyz="-0.0825 0.384 0" />
        <parent link="panda_link4" />
        <child link="panda_link5" />
        <axis xyz="0 0 1" />
        <limit effort="120" lower="-2.8973" upper="2.8973" velocity="2.6100" />
    </joint>
    <link name="panda_link6">
        <visual>
            <geometry>
                <mesh filename="package://franka_description/meshes/visual/link6.dae" />
            </geometry>
        </visual>
        <collision>
            <origin rpy="0 0 0" xyz="0 0 -0.03" />
            <geometry>
                <cylinder length="0.08" radius="0.05" />
            </geometry>
        </collision>
        <collision>
            <origin rpy="0 0 0" xyz="0 0 0.01" />
            <geometry>
                <sphere radius="0.05" />
            </geometry>
        </collision>
        <collision>
            <origin rpy="0 0 0" xyz="0 0 -0.07" />
            <geometry>
                <sphere radius="0.05" />
            </geometry>
        </collision>
        
<inertial>
            <mass value="1.467" />
            <inertia ixx="0.03" iyy="0.03" izz="0.03" ixy="0.0" ixz="0.0" iyz="0.0" />
        </inertial>

    </link>
    <joint name="panda_joint6" type="revolute">
        <safety_controller k_position="100.0" k_velocity="40.0" soft_lower_limit="-0.0175" soft_upper_limit="3.7525" />
        <origin rpy="1.57079632679 0 0" xyz="0 0 0" />
        <parent link="panda_link5" />
        <child link="panda_link6" />
        <axis xyz="0 0 1" />
        <limit effort="120" lower="-0.0175" upper="3.7525" velocity="2.6100" />
    </joint>
    <link name="panda_link7">
        <visual>
            <geometry>
                <mesh filename="package://franka_description/meshes/visual/link7.dae" />
            </geometry>
        </visual>
        <collision>
            <origin rpy="0 0 0" xyz="0 0 0.01" />
            <geometry>
                <cylinder length="0.14" radius="0.04" />
            </geometry>
        </collision>
        <collision>
            <origin rpy="0 0 0" xyz="0 0 0.08" />
            <geometry>
                <sphere radius="0.04" />
            </geometry>
        </collision>
        <collision>
            <origin rpy="0 0 0" xyz="0 0 -0.06" />
            <geometry>
                <sphere radius="0.04" />
            </geometry>
        </collision>
        
<inertial>
            <mass value="0.456" />
            <inertia ixx="0.03" iyy="0.03" izz="0.03" ixy="0.0" ixz="0.0" iyz="0.0" />
        </inertial>

    </link>
    <joint name="panda_joint7" type="revolute">
        <safety_controller k_position="100.0" k_velocity="40.0" soft_lower_limit="-2.8973" soft_upper_limit="2.8973" />
        <origin rpy="1.57079632679 0 0" xyz="0.088 0 0" />
        <parent link="panda_link6" />
        <child link="panda_link7" />
        <axis xyz="0 0 1" />
        <limit effort="120" lower="-2.8973" upper="2.8973" velocity="2.6100" />
    </joint>
    <link name="panda_link8">
        <collision>
            <origin rpy="3.14159265359 1.57079632679 1.57079632679" xyz="0.0424 0.0424 -0.0250" />
            <geometry>
                <cylinder length="0.01" radius="0.03" />
            </geometry>
        </collision>
        <collision>
            <origin rpy="0 0 0" xyz="0.0424 0.0424 -0.02" />
            <geometry>
                <sphere radius="0.03" />
            </geometry>
        </collision>
        <collision>
            <origin rpy="0 0 0" xyz="0.0424 0.0424 -0.03" />
            <geometry>
                <sphere radius="0.03" />
            </geometry>
        </collision>
        
<inertial>
            <mass value="0.1" />
            <inertia ixx="0.03" iyy="0.03" izz="0.03" ixy="0.0" ixz="0.0" iyz="0.0" />
        </inertial>

    </link>
    <joint name="panda_joint8" type="fixed">
        <origin rpy="0 0 0" xyz="0 0 0.107" />
        <parent link="panda_link7" />
        <child link="panda_link8" />
    </joint>
    <!--xacro:hand ns="panda" rpy="0 0 ${-pi/4}" connected_to="panda_link8" safety_distance="0.03"/-->
    
<transmission name="trans_panda_joint1">
        <type>transmission_interface/SimpleTransmission</type>
        <joint name="panda_joint1">
            <hardwareInterface>hardware_interface/PositionJointInterface</hardwareInterface>
        </joint>
        <actuator name="panda_joint1_motor">
            <hardwareInterface>hardware_interface/PositionJointInterface</hardwareInterface>
            <mechanicalReduction>1</mechanicalReduction>
        </actuator>
    </transmission>
    <transmission name="trans_panda_joint2">
        <type>transmission_interface/SimpleTransmission</type>
        <joint name="panda_joint2">
            <hardwareInterface>hardware_interface/PositionJointInterface</hardwareInterface>
        </joint>
        <actuator name="panda_joint2_motor">
            <hardwareInterface>hardware_interface/PositionJointInterface</hardwareInterface>
            <mechanicalReduction>1</mechanicalReduction>
        </actuator>
    </transmission>
    <transmission name="trans_panda_joint3">
        <type>transmission_interface/SimpleTransmission</type>
        <joint name="panda_joint3">
            <hardwareInterface>hardware_interface/PositionJointInterface</hardwareInterface>
        </joint>
        <actuator name="panda_joint3_motor">
            <hardwareInterface>hardware_interface/PositionJointInterface</hardwareInterface>
            <mechanicalReduction>1</mechanicalReduction>
        </actuator>
    </transmission>
    <transmission name="trans_panda_joint4">
        <type>transmission_interface/SimpleTransmission</type>
        <joint name="panda_joint4">
            <hardwareInterface>hardware_interface/PositionJointInterface</hardwareInterface>
        </joint>
        <actuator name="panda_joint4_motor">
            <hardwareInterface>hardware_interface/PositionJointInterface</hardwareInterface>
            <mechanicalReduction>1</mechanicalReduction>
        </actuator>
    </transmission>
    <transmission name="trans_panda_joint5">
        <type>transmission_interface/SimpleTransmission</type>
        <joint name="panda_joint5">
            <hardwareInterface>hardware_interface/PositionJointInterface</hardwareInterface>
        </joint>
        <actuator name="panda_joint5_motor">
            <hardwareInterface>hardware_interface/PositionJointInterface</hardwareInterface>
            <mechanicalReduction>1</mechanicalReduction>
        </actuator>
    </transmission>
    <transmission name="trans_panda_joint6">
        <type>transmission_interface/SimpleTransmission</type>
        <joint name="panda_joint6">
            <hardwareInterface>hardware_interface/PositionJointInterface</hardwareInterface>
        </joint>
        <actuator name="panda_joint6_motor">
            <hardwareInterface>hardware_interface/PositionJointInterface</hardwareInterface>
            <mechanicalReduction>1</mechanicalReduction>
        </actuator>
    </transmission>
    <transmission name="trans_panda_joint7">
        <type>transmission_interface/SimpleTransmission</type>
        <joint name="panda_joint7">
            <hardwareInterface>hardware_interface/PositionJointInterface</hardwareInterface>
        </joint>
        <actuator name="panda_joint7_motor">
            <hardwareInterface>hardware_interface/PositionJointInterface</hardwareInterface>
            <mechanicalReduction>1</mechanicalReduction>
        </actuator>
    </transmission>
    <gazebo>
        <plugin name="gazebo_ros_control" filename="libgazebo_ros_control.so">
            <robotNamespace>/avatar</robotNamespace>
        </plugin>
    </gazebo>
  <gazebo>
    <plugin name="object_controller" filename="libgazebo_ros_planar_move.so">
      <commandTopic>cmd_vel</commandTopic>
      <odometryTopic>odom</odometryTopic>
      <odometryFrame>odom</odometryFrame>
      <odometryRate>100.0</odometryRate>
      <robotBaseFrame>platform</robotBaseFrame>
    </plugin>
  </gazebo>
</robot>
